Workbook

Sheet Savings-Rates-India
A1: Year | B1: Total Savings | C1: Public non-financial corp. | D1: Private non- financial corp. | E1: Public financial corp. | F1: Private financial corp | G1: General Government | H1: Households including NPISH
A2: 2023-24 | B2: 30.74 | C2: 1.51 | D2: 9.54 | E2: 1.39 | F2: 1.11 | G2: -0.95 | H2: 18.13

Sheet Savings-Rates-Institutions
A1: Rate of Savings for Institutional Sectors at Current Prices: Base Year 2011-12
A2: Per cent : 1964-65 to 2023-24
A3: Year | B3: Total Savings | C3: Public non-financial corporations | D3: Private non- financial corporations | E3: Public financial corporations | F3: Private financial corporations | G3: General Government | H3: Households including NPISH
A4: 1964-65 | B4: 11.93
A5: 1965-66 | B5: 13.9
A6: 1966-67 | B6: 13.71
A7: 1967-68 | B7: 12
A8: 1968-69 | B8: 11.88
A9: 1969-70 | B9: 13.95
A10: 1970-71 | B10: 13.87 | D10: 1.26 | F10: 0.03 | G10: 1.47
A11: 1971-72 | B11: 14.67 | D11: 1.35 | F11: 0.04 | G11: 1.36
A12: 1972-73 | B12: 13.76 | D12: 1.29 | F12: 0.03 | G12: 1.32
A13: 1973-74 | B13: 16.34 | D13: 1.45 | F13: 0.02 | G13: 1.64
A14: 1974-75 | B14: 16.13 | D14: 1.67 | F14: 0.02 | G14: 2
A15: 1975-76 | B15: 16.63 | D15: 1.09 | F15: 0.03 | G15: 2.56
A16: 1976-77 | B16: 18.07 | D16: 1.07 | F16: 0.04 | G16: 2.52
A17: 1977-78 | B17: 18.55 | D17: 1.15 | F17: 0.03 | G17: 2.25
A18: 1978-79 | B18: 20.31 | D18: 1.22 | F18: 0.03 | G18: 2.43
A19: 1979-80 | B19: 19.24 | D19: 1.71 | F19: 0.03 | G19: 2.36
A20: 1980-81 | B20: 17.21 | D20: 1.4 | F20: 0.02 | G20: 2.04
A21: 1981-82 | B21: 16.78 | D21: 1.31 | F21: 0.03 | G21: 2.43
... A50: 2010-11 | B50: 36.91 | D50: 8.92 | F50: 1.28 | G50: -0.47
A51: 2011-12 | B51: 34.65 | C51: 1.42 | D51: 8.28 | E51: 1.93 | F51: 1.18 | G51: -1.81 | H51: 23.64
A52: 2012-13 | B52: 33.88 | C52: 1.25 | D52: 8.73 | E52: 1.76 | F52: 1.27 | G52: -1.6 | H52: 22.48
A53: 2013-14 | B53: 32.12 | C53: 1.12 | D53: 9.59 | E53: 1.45 | F53: 1.16 | G53: -1.55 | H53: 20.34
A54: 2014-15 | B54: 32.24 | C54: 1.04 | D54: 10.33 | E54: 1.36 | F54: 1.36 | G54: -1.41 | H54: 19.56
A55: 2015-16 | B55: 31.09 | C55: 1.12 | D55: 11.06 | E55: 1.28 | F55: 0.84 | G55: -1.17 | H55: 17.97
A56: 2016-17 | B56: 31.35 | C56: 1.12 | D56: 10.65 | E56: 1.4 | F56: 0.87 | G56: -0.79 | H56: 18.11
A57: 2017-18 | B57: 32.07 | C57: 1.39 | D57: 10.34 | E57: 1.39 | F57: 0.88 | G57: -1.22 | H57: 19.29
A58: 2018-19 | B58: 31.75 | C58: 1.33 | D58: 9.58 | E58: 0.94 | F58: 0.93 | G58: -1.37 | H58: 20.34
A59: 2019-20 | B59: 29.55 | C59: 1.45 | D59: 9.15 | E59: 1.56 | F59: 1.05 | G59: -2.79 | H59: 19.13
A60: 2020-21 | B60: 29.15 | C60: 1.18 | D60: 9.34 | E60: 1.41 | F60: 1.18 | G60: -6.66 | H60: 22.69
A61: 2021-22 | B61: 31.2 | C61: 1.32 | D61: 10.26 | E61: 1.52 | F61: 0.98 | G61: -2.98 | H61: 20.1
A62: 2022-23 | B62: 30.66 | C62: 1.23 | D62: 9.83 | E62: 1.73 | F62: 1.14 | G62: -1.91 | H62: 18.63
A63: 2023-24 | B63: 30.74 | C63: 1.51 | D63: 9.54 | E63: 1.39 | F63: 1.11 | G63: -0.95 | H63: 18.13

Sheet GCF-Financing
A1: Sources of Financing Gross Capital Formation at Current Prices: Base Year 2011-12
A2: Rs. Million : 1997-98 to 2020-21
A3: Year | B3: 2011-12 | C3: 2012-13 | D3: 2013-14 | E3: 2014-15 | F3: 2015-16 | G3: 2016-17 | H3: 2017-18 | I3: 2018-19 | J3: 2019-20 | K3: 2020-21
A4: Total Savings | B4: 34030080 | C4: 38471220 | D4: 37941350 | E4: 41797790 | F4: 44226590 | G4: 49180770 | H4: 57915730 | I4: 63960530 | J4: 61612130 | K4: 54031100
A5: Net capital inflow from rest of the world | B5: 3761710 | C5: 4779200 | D5: 1859420 | E5: 1598220 | F5: 1403990 | G5: 929640 | H5: 3108320 | I5: 3956620 | J5: 1652710 | K5: -1893360
A6: Gross saving | B6: 30268370 | C6: 33692020 | D6: 36081930 | E6: 40199570 | F6: 42822590 | G6: 48251130 | H6: 54807410 | I6: 60003900 | J6: 59959420 | K6: 55924460
A7: Non financial corporations save | B7: 8471340 | C7: 9921930 | D7: 12035360 | E7: 14170530 | F7: 16771840 | G7: 18110190 | H7: 20053740 | I7: 20612170 | J7: 21251810 | K7: 19900770
A8: Public non-financial corporations | B8: 1237690 | C8: 1239810 | D8: 1262500 | E8: 1291080 | F8: 1540150 | G8: 1721860 | H8: 2374830 | I8: 2507970 | J8: 2917520 | K8: 2760590
A9: Departmental enterprises | B9: 247230 | C9: 312820 | D9: 326880 | E9: 392530 | F9: 476200 | G9: 443000 | H9: 503520 | I9: 551280 | J9: 531610 | K9: 528980
A10: Non-departmental enterprises | B10: 990460 | C10: 926990 | D10: 935620 | E10: 898550 | F10: 1063950 | G10: 1278860 | H10: 1871310 | I10: 1956690 | J10: 2385900 | K10: 2231610
A11: Private non-financial corporations | B11: 7233650 | C11: 8682120 | D11: 10772860 | E11: 12879440 | F11: 15231690 | G11: 16388330 | H11: 17678910 | I11: 18104210 | J11: 18334290 | K11: 17140180
A12: Financial corporations save | B12: 2723710 | C12: 3006260 | D12: 2930840 | E12: 3390270 | F12: 2916410 | G12: 3484090 | H12: 3870280 | I12: 3537190 | J12: 5829460 | K12: 5572630
A13: Public financial corporations | B13: 1689310 | C13: 1748330 | D13: 1631840 | E13: 1699080 | F13: 1765130 | G13: 2152580 | H13: 2371270 | I13: 1779640 | J13: 3121720 | K13: 2850350
A14: Departmental enterprises | B14: 42840 | C14: 51720 | D14: 59610 | E14: 67220 | F14: 78780 | G14: 71590 | H14: 82180 | I14: 84510 | J14: 88750 | K14: 77140
A15: Non-departmental enterprises | B15: 1646470 | C15: 1696610 | D15: 1572230 | E15: 1631860 | F15: 1686360 | G15: 2081000 | H15: 2289090 | I15: 1695130 | J15: 3032970 | K15: 2773210
... A17: General Government Saving | B17: -1582340 | C17: -1588970 | D17: -1737290 | E17: -1752270 | F17: -1614780 | G17: -1214490 | H17: -2082570 | I17: -2591270 | J17: -6413320 | K17: -13454780
A18: Household sector | B18: 20655660 | C18: 22352800 | D18: 22853010 | E18: 24391040 | F18: 24749130 | G18: 27871340 | H18: 32965960 | I18: 38445820 | J18: 39291480 | K18: 43905840 | L18: =K19+K22+K23 -> 43905840
A19: Net financial saving (household) | B19: 6426090 | C19: 7336160 | D19: 8320910 | E19: 8804160 | F19: 11108450 | G19: 11460290 | H19: 13057050 | I19: 14924450 | J19: 16124680 | K19: 23037080 | L19: =K20-K21 -> 23037080
A20: Gross financial saving | B20: 9327290 | C20: 10640410 | D20: 11907700 | E20: 12572470 | F20: 14962320 | G20: 16146770 | H20: 20564050 | I20: 22636900 | J20: 23990870 | K20: 31089970
A21: Financial liabilities | B21: 2901200 | C21: 3304250 | D21: 3586790 | E21: 3768320 | F21: 3853880 | G21: 4686480 | H21: 7507000 | I21: 7712450 | J21: 7866190 | K21: 8052890
A22: Saving in physical assets | B22: 13893220 | C22: 14650130 | D22: 14164280 | E22: 15131270 | F22: 13175990 | G22: 15945730 | H22: 19442260 | I22: 23094630 | J22: 22735440 | K22: 20484320
A23: Saving in the form of gold & silver ornaments | B23: 336350 | C23: 366500 | D23: 367820 | E23: 455620 | F23: 464690 | G23: 465320 | H23: 466650 | I23: 426730 | J23: 431360 | K23: 384440
A25: Total | B25: 32057160 | C25: 35394970 | D25: 36602420 | E25: 40630900 | F25: 42195700 | G25: 44767540 | H25: 50531810 | I25: 58866570 | J25: 58721170 | K25: 52523090 | L25: 20000550 | M25: 20445960 | N25: 23799360 | O25: 28703880 | P25: 32057160 | Q25: 35394970 | R25: 36602420 | S25: 40630900 | T25: 42195700 | U25: 44767540 | V25: 50531810 | W25: 58866570 | X25: 58721170 | Y25: 52523090

Sheet RBI-Rates
A1: CRR, SLR, Repo, Reverse Repo and Bank Rate
A2: Per cent : Oct 2020 to Sep 2025
A3: Month | B3: CRR | C3: SLR | D3: Repo rate | E3: Reverse repo rate | F3: SDF | G3: MSF | H3: Bank rate
A4: 44105 | B4: 3 | C4: 18 | D4: 4 | E4: 3.35 | G4: 4.25 | H4: 4.25
A5: 44136 | B5: 3 | C5: 18 | D5: 4 | E5: 3.35 | G5: 4.25 | H5: 4.25
A6: 44166 | B6: 3 | C6: 18 | D6: 4 | E6: 3.35 | G6: 4.25 | H6: 4.25
A7: 44197 | B7: 3 | C7: 18 | D7: 4 | E7: 3.35 | G7: 4.25 | H7: 4.25
A8: 44228 | B8: 3 | C8: 18 | D8: 4 | E8: 3.35 | G8: 4.25 | H8: 4.25
A9: 44256 | B9: 3 | C9: 18 | D9: 4 | E9: 3.35 | G9: 4.25 | H9: 4.25
A10: 44287 | B10: 3.5 | C10: 18 | D10: 4 | E10: 3.35 | G10: 4.25 | H10: 4.25
A11: 44317 | B11: 4 | C11: 18 | D11: 4 | E11: 3.35 | G11: 4.25 | H11: 4.25
A12: 44348 | B12: 4 | C12: 18 | D12: 4 | E12: 3.35 | G12: 4.25 | H12: 4.25
A13: 44378 | B13: 4 | C13: 18 | D13: 4 | E13: 3.35 | G13: 4.25 | H13: 4.25
A14: 44409 | B14: 4 | C14: 18 | D14: 4 | E14: 3.35 | G14: 4.25 | H14: 4.25
A15: 44440 | B15: 4 | C15: 18 | D15: 4 | E15: 3.35 | G15: 4.25 | H15: 4.25
... A21: 44621 | B21: 4 | C21: 18 | D21: 4 | E21: 3.35 | G21: 4.25 | H21: 4.25
A22: 44652 | B22: 4 | C22: 18 | D22: 4 | E22: 3.35 | F22: 3.75 | G22: 4.25 | H22: 4.25
A23: 44682 | B23: 4.5 | C23: 18 | D23: 4.4 | E23: 3.35 | F23: 4.15 | G23: 4.65 | H23: 4.65
A24: 44713 | B24: 4.5 | C24: 18 | D24: 4.9 | E24: 3.35 | F24: 4.65 | G24: 5.15 | H24: 5.15
A25: 44743 | B25: 4.5 | C25: 18 | D25: 4.9 | E25: 3.35 | F25: 4.65 | G25: 5.15 | H25: 5.15
A26: 44774 | B26: 4.5 | C26: 18 | D26: 5.4 | E26: 3.35 | F26: 5.15 | G26: 5.65 | H26: 5.65
A27: 44805 | B27: 4.5 | C27: 18 | D27: 5.9 | E27: 3.35 | F27: 5.65 | G27: 6.15 | H27: 6.15
A28: 44835 | B28: 4.5 | C28: 18 | D28: 5.9 | E28: 3.35 | F28: 5.65 | G28: 6.15 | H28: 6.15
A29: 44866 | B29: 4.5 | C29: 18 | D29: 5.9 | E29: 3.35 | F29: 5.65 | G29: 6.15 | H29: 6.15
A30: 44896 | B30: 4.5 | C30: 18 | D30: 6.25 | E30: 3.35 | F30: 6 | G30: 6.5 | H30: 6.5
A31: 44927 | B31: 4.5 | C31: 18 | D31: 6.25 | E31: 3.35 | F31: 6 | G31: 6.5 | H31: 6.5
A32: 44958 | B32: 4.5 | C32: 18 | D32: 6.5 | E32: 3.35 | F32: 6.25 | G32: 6.75 | H32: 6.75
A33: 44986 | B33: 4.5 | C33: 18 | D33: 6.5 | E33: 3.35 | F33: 6.25 | G33: 6.75 | H33: 6.75
... A63: 45901 | B63: 3.75 | C63: 18 | D63: 5.5 | E63: 3.35 | F63: 5.25 | G63: 5.75 | H63: 5.75

Sheet WPI-Inflation
A1: Wholesale Price Index (WPI): General Index, Groups and Sub-groups including Food Group: Base Year: 2011-12
A2: Y-o-Y % change : September 2020 to August 2025
A3: Month | B3: All commodities | C3: Primary articles | D3: Primary articles | E3: Primary articles | F3: Primary articles | G3: Primary articles | H3: Fuel & power | I3: Fuel & power | J3: Fuel & power | K3: Fuel & power | L3: Manufactured products | M3: Food group
C4: Total | D4: Food articles | E4: Non-food articles | F4: Minerals | G4: Crude petroleum & natural gas | H4: Total | I4: Coal | J4: Mineral oils | K4: Electricity
A5: Weight | B5: 100 | C5: 22.61756 | D5: 15.25585 | E5: 4.11894 | F5: 0.83317 | G5: 2.4096 | H5: 13.1519 | I5: 2.13813 | J5: 7.94968 | K5: 3.06409 | L5: 64.23054 | M5: 24.37758
A6: 44075 | B6: 1.32 | C6: 4.06 | D6: 8.37 | E6: -1.81 | F6: -6.01 | G6: -23.41 | H6: -8.65 | I6: 1.28 | J6: -14.36 | K6: -4.27 | L6: 1.87 | M6: 7.19
A7: 44105 | B7: 1.31 | C7: 4.33 | D7: 7.05 | E7: 2.93 | F7: -0.2 | G7: -22.95 | H7: -11.14 | I7: -0.08 | J7: -18.32 | K7: -4.27 | L7: 2.21 | M7: 6.18
A8: 44136 | B8: 2.29 | C8: 3.8 | D8: 4.61 | E8: 8.66 | F8: 10.38 | G8: -21.51 | H8: -7.01 | I8: 0 | J8: -15.92 | K8: 6.73 | L8: 3.23 | M8: 4.79
A9: 44166 | B9: 1.95 | C9: -0.6 | D9: -0.92 | E9: 2.99 | F9: 16.67 | G9: -15.99 | H9: -6.1 | I9: 0.4 | J9: -11.17 | K9: -0.85 | L9: 4.49 | M9: 1.11
A10: 44197 | B10: 2.51 | C10: -1.56 | D10: -2.93 | E10: 4.24 | F10: 12.35 | G10: -9.44 | H10: -3.82 | I10: 0.4 | J10: -6.82 | K10: -0.85 | L10: 5.47 | M10: -0.26
A11: 44228 | B11: 4.83 | C11: 3.01 | D11: 1.81 | E11: 4.02 | F11: 17.09 | G11: 5.29 | H11: 2.03 | I11: 0.32 | J11: 3.14 | K11: 0.86 | L11: 6.06 | M11: 3.58
A12: 44256 | B12: 7.89 | C12: 7.28 | D12: 3.44 | E12: 11.94 | F12: 19.96 | G12: 38.49 | H12: 9.75 | I12: 0.32 | J12: 19.61 | K12: -2.46 | L12: 7.84 | M12: 5.63
A13: 44287 | B13: 10.74 | C13: 9.94 | D13: 4.6 | E13: 15.58 | F13: 20.64 | G13: 80.76 | H13: 21.27 | I13: 0.63 | J13: 46.03 | K13: -2.46 | L13: 9.44 | M13: 7.52
A14: 44317 | B14: 13.11 | C14: 9.4 | D14: 4.25 | E14: 18.37 | F14: 13.25 | G14: 59.52 | H14: 36.74 | I14: 0.71 | J14: 83.05 | K14: 0.19 | L14: 11.25 | M14: 8.25
A15: 44348 | B15: 12.07 | C15: 8.59 | D15: 3.28 | E15: 18.63 | F15: 15.33 | G15: 46.97 | H15: 29.32 | I15: 0.71 | J15: 61.81 | K15: -2.77 | L15: 10.96 | M15: 6.72
A16: 44378 | B16: 11.57 | C16: 6.34 | D16: 0.12 | E16: 22.94 | F16: 12.55 | G16: 42.25 | H16: 27.01 | I16: 0.87 | J16: 53.7 | K16: -2.77 | L16: 11.46 | M16: 4.52
A17: 44409 | B17: 11.64 | C17: 5.93 | D17: -0.8 | E17: 28.69 | F17: 7.16 | G17: 34.49 | H17: 28.15 | I17: 1.03 | J17: 52.68 | K17: 2.9 | L17: 11.56 | M17: 3.76
... A65: 45870 | B65: 0.52 | C65: -2.1 | D65: -3.06 | E65: 5.56 | F65: 3.3 | G65: -9.87 | H65: -3.17 | I65: 0.52 | J65: -4.72 | K65: -1.11 | L65: 2.55 | M65: 0.21
A67: Cumulative | B67: Apr-Aug | C67: Apr-Aug | D67: Apr-Aug | E67: Apr-Aug | F67: Apr-Aug | G67: Apr-Aug | H67: Apr-Aug | I67: Apr-Aug | J67: Apr-Aug | K67: Apr-Aug | L67: Apr-Aug | M67: Apr-Aug
A68: 2021-22 | B68: 11.82 | C68: 8 | D68: 2.24 | E68: 20.86 | F68: 13.68 | G68: 50.66 | H68: 28.31 | I68: 0.79 | J68: 58.37 | K68: -0.99 | L68: 10.93 | M68: 6.12
A69: 2022-23 | B69: 14.94 | C69: 16.42 | D69: 11.45 | E69: 17.31 | F69: 10.89 | G69: 70.27 | H69: 43.59 | I69: 3.26 | J69: 62.36 | K69: 25.72 | L69: 9.34 | M69: 10.17
A70: 2023-24 | B70: -2.07 | C70: 2.37 | D70: 6.68 | E70: -7.7 | F70: 5.16 | G70: -10.25 | H70: -8.13 | I70: 3.74 | J70: -14.29 | K70: 5.68 | L70: -2.6 | M70: 2.41
A71: 2024-25 | B71: 2.14 | C71: 5.42 | D71: 6.97 | E71: -2.68 | F71: 6.29 | G71: 7.5 | H71: 0.39 | I71: -0.56 | J71: 1.39 | K71: -1.91 | L71: 0.98 | M71: 5.84
A72: 2025-26 | B72: 0.14 | C72: -2.61 | D72: -2.85 | E72: 2.8 | F72: 1.27 | G72: -11.81 | H72: -3.46 | I72: 0.5 | J72: -5.83 | K72: 0.93 | L72: 2.25 | M72: 0.57

Sheet CPI-Level
A1: Consumer Price Index (CPI): Combined, Urban and Rural: General Index, Core Index and Non-core Index: Base Year 2012
A2: Index numbers : September 2020 to August 2025
B3: Combined | C3: Urban | D3: Rural | E3: Combined | F3: Urban | G3: Rural | H3: Combined | I3: Urban | J3: Rural | K3: Combined | L3: Combined | M3: Combined | N3: Combined
A4: Weight | B4: 100 | C4: 100 | D4: 100 | E4: 54.11 | F4: 64.8 | G4: 44.81 | H4: 45.9 | I4: 35.2 | J4: 55.19 | K4: 51.72 | L4: 48.29 | M4: 42.2 | N4: 57.8
A5: Month | B5: CPI general index | C5: CPI general index | D5: CPI general index | E5: Core CPI index (CPI excluding food group and fuel & light group) | F5: Core CPI index (CPI excluding food group and fuel & light group) | G5: Core CPI index (CPI excluding food group and fuel & light group) | H5: Non-core CPI index (includes food group and fuel & light group) | I5: Non-core CPI index (includes food group and fuel & light group) | J5: Non-core CPI index (includes food group and fuel & light group) | K5: Core Core CPI index (CPI excluding food group, fuel & light group and petrol, diesel & other fuels for vehicle) | L5: Non-core-core CPI index (includes food group, fuel & light group and petrol, diesel & other fuels for vehicle) | M5: Super core CPI index (excluding food group, fuel & light group and petrol, diesel & other fuels for vehicle and house rent) | N5: Non-super-core CPI index (includes food group, fuel & light group and petrol, diesel & other fuels for vehicle and house rent)
A6: 43009 | B6: 136.1 | C6: 133.5 | D6: 138.3 | E6: 134.2 | F6: 131.9 | G6: 137.1 | H6: 138.3 | I6: 136.5 | J6: 139.3 | K6: 135.7 | L6: 136.5 | M6: 135.3 | N6: 136.7
A7: 43040 | B7: 137.6 | C7: 134.8 | D7: 140 | E7: 135.1 | F7: 132.7 | G7: 138.2 | H7: 140.6 | I7: 138.8 | J7: 141.5 | K7: 136.6 | L7: 138.7 | M7: 136.1 | N7: 138.7
A8: 43070 | B8: 137.2 | C8: 134.1 | D8: 139.8 | E8: 135.4 | F8: 133 | G8: 138.4 | H8: 139.2 | I8: 136.1 | J8: 141 | K8: 136.9 | L8: 137.5 | M8: 136.3 | N8: 137.7
A9: 43101 | B9: 136.9 | C9: 134.1 | D9: 139.3 | E9: 136 | F9: 133.9 | G9: 138.7 | H9: 137.9 | I9: 134.5 | J9: 139.7 | K9: 137.4 | L9: 136.3 | M9: 136.7 | N9: 137
A10: 43132 | B10: 136.4 | C10: 134 | D10: 138.5 | E10: 136.5 | F10: 134.6 | G10: 138.9 | H10: 136.2 | I10: 132.8 | J10: 138.1 | K10: 137.8 | L10: 134.8 | M10: 137 | N10: 135.9
A11: 43160 | B11: 136.5 | C11: 134 | D11: 138.7 | E11: 137.2 | F11: 135.2 | G11: 139.7 | H11: 135.7 | I11: 131.7 | J11: 137.9 | K11: 138.5 | L11: 134.3 | M11: 137.7 | N11: 135.6
A12: 43191 | B12: 137.1 | C12: 134.8 | D12: 139.1 | E12: 138.1 | F12: 136.1 | G12: 140.6 | H12: 135.9 | I12: 132.3 | J12: 138 | K12: 139.4 | L12: 134.6 | M12: 138.6 | N12: 136
A13: 43221 | B13: 137.8 | C13: 135.4 | D13: 139.8 | E13: 138.8 | F13: 136.7 | G13: 141.4 | H13: 136.6 | I13: 133 | J13: 138.5 | K13: 140 | L13: 135.3 | M13: 139.3 | N13: 136.7
A14: 43252 | B14: 138.5 | C14: 136.2 | D14: 140.5 | E14: 139 | F14: 136.8 | G14: 141.8 | H14: 138 | I14: 135.2 | J14: 139.5 | K14: 140.2 | L14: 136.8 | M14: 139.7 | N14: 137.7
A15: 43282 | B15: 139.8 | C15: 137.5 | D15: 141.8 | E15: 139.6 | F15: 137.6 | G15: 142.1 | H15: 140 | I15: 137.4 | J15: 141.6 | K15: 140.8 | L15: 138.7 | M15: 140.2 | N15: 139.5
A16: 43313 | B16: 140.4 | C16: 138 | D16: 142.5 | E16: 140.3 | F16: 138.4 | G16: 142.7 | H16: 140.6 | I16: 137.3 | J16: 142.4 | K16: 141.5 | L16: 139.3 | M16: 140.8 | N16: 140.2
A17: 43344 | B17: 140.2 | C17: 138.1 | D17: 142.1 | E17: 141 | F17: 139.2 | G17: 143.3 | H17: 139.4 | I17: 136.1 | J17: 141.2 | K17: 142.1 | L17: 138.4 | M17: 141.3 | N17: 139.6
... A34: 43862 | B34: 149.1 | C34: 147.7 | D34: 150.4 | E34: 149 | F34: 146.8 | G34: 151.7 | H34: 149.3 | I34: 149.2 | J34: 149.5 | K34: 150.9 | L34: 147.3 | M34: 150 | N34: 148.5
A35: 43891 | B35: 148.6 | C35: 147.3 | D35: 149.8 | E35: 149.2 | F35: 146.9 | G35: 152 | H35: 148 | I35: 147.9 | J35: 148 | L35: 148 | N35: 148
A36: 43922 | B36: 151.4 | C36: 150.9 | D36: 151.9 | E36: 150.9 | F36: 149.9 | G36: 152.2 | H36: 152 | I36: 152.8 | J36: 151.6 | L36: 152 | N36: 152
A37: 43952 | B37: 150.9 | C37: 150.6 | D37: 151.2 | E37: 151.4 | F37: 150.2 | G37: 152.8 | H37: 150.4 | I37: 151.4 | J37: 149.9 | L37: 150.4 | N37: 150.4
A38: 43983 | B38: 151.8 | C38: 150.8 | D38: 152.7 | E38: 151.9 | F38: 149.2 | G38: 155.3 | H38: 151.7 | I38: 153.8 | J38: 150.6 | K38: 153.8 | L38: 149.7 | M38: 153.7 | N38: 150.5
A39: 44013 | B39: 153.9 | C39: 152.9 | D39: 154.7 | E39: 153.2 | F39: 151 | G39: 156 | H39: 154.7 | I39: 156.6 | J39: 153.6 | K39: 154.8 | L39: 152.9 | M39: 154.7 | N39: 153.3
A40: 44044 | B40: 154.7 | C40: 154 | D40: 155.4 | E40: 154.1 | F40: 152 | G40: 156.7 | H40: 155.6 | I40: 157.7 | J40: 154.4 | K40: 155.7 | L40: 153.8 | M40: 155.6 | N40: 154.2
A41: 44075 | B41: 156.4 | C41: 155.2 | D41: 157.5 | E41: 154.4 | F41: 152.2 | G41: 157.2 | H41: 158.8 | I41: 160.8 | J41: 157.8 | K41: 156 | L41: 156.9 | M41: 156 | N41: 156.8
A42: 44105 | B42: 158.4 | C42: 156.7 | D42: 159.8 | E42: 155.1 | F42: 153 | G42: 157.7 | H42: 162.2 | I42: 163.5 | J42: 161.5 | K42: 156.7 | L42: 160.1 | M42: 156.4 | N42: 159.7
A43: 44136 | B43: 158.9 | C43: 156.9 | D43: 160.7 | E43: 155.7 | F43: 153.5 | G43: 158.4 | H43: 162.8 | I43: 163.2 | J43: 162.6 | K43: 157.4 | L43: 160.7 | M43: 157.2 | N43: 160.3
A44: 44166 | B44: 157.3 | C44: 156 | D44: 158.5 | E44: 156.2 | F44: 153.8 | G44: 159.2 | H44: 158.7 | I44: 160.2 | J44: 157.9 | K44: 157.7 | L44: 156.9 | M44: 157.8 | N44: 157
A45: 44197 | B45: 156.3 | C45: 155.8 | D45: 156.8 | E45: 157.1 | F45: 154.8 | G45: 160.1 | H45: 155.5 | I45: 157.6 | J45: 154.3 | K45: 158.6 | L45: 153.9 | M45: 158.6 | N45: 154.7
A46: 44228 | B46: 156.6 | C46: 156.5 | D46: 156.7 | E46: 157.9 | F46: 155.7 | G46: 160.7 | H46: 155 | I46: 158 | J46: 153.5 | K46: 159.2 | L46: 153.8 | M46: 159.2 | N46: 154.7
A47: 44256 | B47: 156.8 | C47: 156.9 | D47: 156.7 | E47: 158.3 | F47: 156.2 | G47: 160.9 | H47: 155.1 | I47: 158.3 | J47: 153.4 | K47: 159.5 | L47: 154 | M47: 159.4 | N47: 154.9
A48: 44287 | B48: 157.8 | C48: 158 | D48: 157.6 | E48: 159.1 | F48: 157.1 | G48: 161.6 | H48: 156.3 | I48: 159.7 | J48: 154.4 | K48: 160.4 | L48: 155.1 | M48: 160.2 | N48: 156.1
A49: 44317 | B49: 160.4 | C49: 159.5 | D49: 161.1 | E49: 161.1 | F49: 158.1 | G49: 164.9 | H49: 159.4 | I49: 162.2 | J49: 157.9 | K49: 162.4 | L49: 158.2 | M49: 162.7 | N49: 158.7
... A100: 45870 | B100: 197 | C100: 195 | D100: 198.7 | E100: 195.3 | F100: 191.2 | G100: 200.5 | H100: 198.9 | I100: 201.9 | J100: 197.3 | K100: 197.7 | L100: 196.2 | M100: 200.4 | N100: 194.4
A101: Cumulative | B101: Apr-Aug | C101: Apr-Aug | D101: Apr-Aug | E101: Apr-Aug | F101: Apr-Aug | G101: Apr-Aug | H101: Apr-Aug | I101: Apr-Aug | J101: Apr-Aug | K101: Apr-Aug | L101: Apr-Aug | M101: Apr-Aug | N101: Apr-Aug
A102: 2021-22 | B102: 161 | C102: 160.4 | D102: 161.5 | E102: 161.5 | F102: 158.7 | G102: 165 | H102: 160.4 | I102: 163.4 | J102: 158.7 | K102: 162.6 | L102: 159.3 | M102: 162.9 | N102: 159.6
A103: 2022-23 | B103: 172.4 | C103: 171.4 | D103: 173.3 | E103: 171.6 | F103: 168.3 | G103: 175.7 | H103: 173.3 | I103: 177.1 | J103: 171.3 | K103: 172.5 | L103: 172.2 | M103: 173.7 | N103: 171.4
A104: 2023-24 | B104: 182.1 | C104: 180.9 | D104: 183.1 | E104: 180.3 | F104: 176.8 | G104: 184.8 | H104: 184.2 | I104: 188.6 | J104: 181.8 | K104: 181.9 | L104: 182.3 | M104: 183.5 | N104: 181.1
A105: 2024-25 | B105: 190.1 | C105: 187.8 | D105: 192.2 | E105: 186.2 | F105: 182.5 | G105: 190.9 | H105: 194.7 | I105: 197.6 | J105: 193.2 | K105: 188.2 | L105: 192.2 | M105: 190.1 | N105: 190.1
A106: 2025-26 | B106: 194.6 | C106: 192.9 | D106: 196 | E106: 194 | F106: 190 | G106: 199.2 | H106: 195.2 | I106: 198.1 | J106: 193.5 | K106: 196.4 | L106: 192.6 | M106: 199 | N106: 191.3

Sheet CPI-Inflation
A1: Consumer Price Index (CPI): Combined, Urban and Rural: General Index, Core Index and Non-core Index: Base Year 2012
A2: Y-o-Y % change : September 2020 to August 2025
B3: Combined | C3: Urban | D3: Rural | E3: Combined | F3: Urban | G3: Rural | H3: Combined | I3: Urban | J3: Rural | K3: Combined | L3: Combined | M3: Combined | N3: Combined
A4: Weight | B4: 100 | C4: 100 | D4: 100 | E4: 54.11 | F4: 64.8 | G4: 44.81 | H4: 45.9 | I4: 35.2 | J4: 55.19 | K4: 51.72 | L4: 48.29 | M4: 42.2 | N4: 57.8
A5: Month | B5: CPI general index | C5: CPI general index | D5: CPI general index | E5: Core CPI index (CPI excluding food group and fuel & light group) | F5: Core CPI index (CPI excluding food group and fuel & light group) | G5: Core CPI index (CPI excluding food group and fuel & light group) | H5: Non-core CPI index (includes food group and fuel & light group) | I5: Non-core CPI index (includes food group and fuel & light group) | J5: Non-core CPI index (includes food group and fuel & light group) | K5: Core Core CPI index (CPI excluding food group, fuel & light group and petrol, diesel & other fuels for vehicle) | L5: Non-core-core CPI index (includes food group, fuel & light group and petrol, diesel & other fuels for vehicle) | M5: Super core CPI index (excluding food group, fuel & light group and petrol, diesel & other fuels for vehicle and house rent) | N5: Non-super-core CPI index (includes food group, fuel & light group and petrol, diesel & other fuels for vehicle and house rent)
A6: 43556 | B6: 2.99 | C6: 4.3 | D6: 1.87 | E6: 4.29 | F6: 4.18 | G6: 4.45 | H6: 1.32 | I6: 4.48 | J6: -0.39 | K6: 4.56 | L6: 1.17 | M6: 4.55 | N6: 1.77
A7: 43586 | B7: 3.05 | C7: 4.51 | D7: 1.86 | E7: 4 | F7: 3.97 | G7: 4.09 | H7: 1.93 | I7: 5.56 | J7: 0.09 | K7: 4.35 | L7: 1.63 | M7: 4.25 | N7: 2.15
A8: 43617 | B8: 3.18 | C8: 4.33 | D8: 2.21 | E8: 3.95 | F8: 3.86 | G8: 4.01 | H8: 2.25 | I8: 5.26 | J8: 0.64 | K8: 4.37 | L8: 1.83 | M8: 4.27 | N8: 2.32
A9: 43647 | B9: 3.15 | C9: 4.22 | D9: 2.19 | E9: 4.07 | F9: 3.93 | G9: 4.26 | H9: 1.96 | I9: 4.65 | J9: 0.48 | K9: 4.42 | L9: 1.65 | M9: 4.34 | N9: 2.19
A10: 43678 | B10: 3.28 | C10: 4.49 | D10: 2.25 | E10: 4.01 | F10: 3.88 | G10: 4.21 | H10: 2.29 | I10: 5.51 | J10: 0.59 | K10: 4.45 | L10: 1.92 | M10: 4.36 | N10: 2.41
A11: 43709 | B11: 3.99 | C11: 4.78 | D11: 3.24 | E11: 3.77 | F11: 3.58 | G11: 4 | H11: 4 | I11: 6.89 | J11: 2.51 | K11: 4.29 | L11: 3.4 | M11: 4.19 | N11: 3.63
A12: 43739 | B12: 4.62 | C12: 5.11 | D12: 4.29 | E12: 3.31 | F12: 3.4 | G12: 3.23 | H12: 6.36 | I12: 8.33 | J12: 5.23 | K12: 3.82 | L12: 5.69 | M12: 3.63 | N12: 5.52
A13: 43770 | B13: 5.54 | C13: 5.76 | D13: 5.27 | E13: 3.26 | F13: 3.52 | G13: 3.02 | H13: 8.15 | I13: 9.81 | J13: 7.27 | K13: 3.54 | L13: 7.68 | M13: 3.3 | N13: 7.15
A14: 43800 | B14: 7.35 | C14: 7.46 | D14: 7.33 | E14: 3.55 | F14: 4.11 | G14: 2.91 | H14: 12.09 | I14: 13.75 | J14: 11.11 | K14: 3.47 | L14: 11.86 | M14: 3.26 | N14: 10.56
A15: 43831 | B15: 7.59 | C15: 7.39 | D15: 7.73 | E15: 3.95 | F15: 4.3 | G15: 3.51 | H15: 12.1 | I15: 13.3 | J15: 11.46 | K15: 3.83 | L15: 11.92 | M15: 3.72 | N15: 10.53
A16: 43862 | B16: 6.58 | C16: 6.57 | D16: 6.67 | E16: 3.89 | F16: 4.14 | G16: 3.48 | H16: 10.13 | I16: 11.18 | J16: 9.52 | K16: 3.89 | L16: 9.85 | M16: 3.79 | N16: 8.86
A17: 43891 | B17: 5.84 | C17: 5.59 | D17: 6.09 | E17: 3.79 | F17: 3.93 | G17: 3.58 | H17: 8.42 | I17: 8.78 | J17: 8.25 | L17: 9.63 | N17: 7.79
A18: 43922 | B18: 7.22 | C18: 7.33 | D18: 7.2 | E18: 4.76 | F18: 5.69 | G18: 3.67 | H18: 10.39 | I18: 10.54 | J18: 10.28 | L18: 11.64 | N18: 9.84
A19: 43952 | B19: 6.27 | C19: 6.43 | D19: 6.18 | E19: 4.88 | F19: 5.72 | G19: 3.81 | H19: 8.06 | I19: 7.85 | J19: 8.16 | L19: 9.36 | N19: 7.74
A20: 43983 | B20: 6.23 | C20: 6.12 | D20: 6.34 | E20: 5.13 | F20: 5 | G20: 5.27 | H20: 7.5 | I20: 8.07 | J20: 7.2 | K20: 5.13 | L20: 7.5 | M20: 5.53 | N20: 6.78
A21: 44013 | B21: 6.73 | C21: 6.7 | D21: 6.76 | E21: 5.45 | F21: 5.57 | G21: 5.31 | H21: 8.31 | I21: 8.97 | J21: 7.96 | K21: 5.29 | L21: 8.42 | M21: 5.79 | N21: 7.51
A22: 44044 | B22: 6.69 | C22: 6.8 | D22: 6.66 | E22: 5.57 | F22: 5.67 | G22: 5.39 | H22: 8.21 | I22: 8.89 | J22: 7.77 | K22: 5.35 | L22: 8.35 | M22: 5.92 | N22: 7.4
A23: 44075 | B23: 7.27 | C23: 7.26 | D23: 7.36 | E23: 5.51 | F23: 5.52 | G23: 5.47 | H23: 9.55 | I23: 10.57 | J23: 8.98 | K23: 5.29 | L23: 9.64 | M23: 5.92 | N23: 8.41
A24: 44105 | B24: 7.61 | C24: 7.33 | D24: 7.75 | E24: 5.66 | F24: 5.69 | G24: 5.59 | H24: 9.75 | I24: 10.27 | J24: 9.5 | K24: 5.51 | L24: 9.75 | M24: 6.06 | N24: 8.61
A25: 44136 | B25: 6.93 | C25: 6.73 | D25: 7.2 | E25: 5.8 | F25: 5.75 | G25: 5.8 | H25: 8.39 | I25: 8.55 | J25: 8.3 | K25: 5.67 | L25: 8.44 | M25: 6.29 | N25: 7.53
A26: 44166 | B26: 4.59 | C26: 5.19 | D26: 4.07 | E26: 5.68 | F26: 5.6 | G26: 5.73 | H26: 3.35 | I26: 4.48 | J26: 2.77 | K26: 5.48 | L26: 3.63 | M26: 6.05 | N26: 3.53
A27: 44197 | B27: 4.06 | C27: 5.13 | D27: 3.23 | E27: 5.75 | F27: 5.74 | G27: 5.78 | H27: 2.23 | I27: 3.99 | J27: 1.19 | K27: 5.54 | L27: 2.59 | M27: 6.11 | N27: 2.67
A28: 44228 | B28: 5.03 | C28: 5.96 | D28: 4.19 | E28: 5.99 | F28: 6.04 | G28: 5.95 | H28: 3.82 | I28: 5.89 | J28: 2.67 | K28: 5.54 | L28: 4.42 | M28: 6.13 | N28: 4.17
A29: 44256 | B29: 5.52 | C29: 6.52 | D29: 4.61 | E29: 6.11 | F29: 6.3 | G29: 5.86 | H29: 4.81 | I29: 7.07 | J29: 3.61 | L29: 4.06 | N29: 4.68
A30: 44287 | B30: 4.23 | C30: 4.71 | D30: 3.75 | E30: 5.45 | F30: 4.82 | G30: 6.16 | H30: 2.81 | I30: 4.55 | J30: 1.85 | L30: 2.01 | N30: 2.68
A31: 44317 | B31: 6.3 | C31: 5.91 | D31: 6.55 | E31: 6.43 | F31: 5.25 | G31: 7.94 | H31: 5.98 | I31: 7.14 | J31: 5.35 | L31: 5.15 | N31: 5.5
A32: 44348 | B32: 6.26 | C32: 6.37 | D32: 6.16 | E32: 6.35 | F32: 6.21 | G32: 6.52 | H32: 6.19 | I32: 6.61 | J32: 5.96 | K32: 5.68 | L32: 6.87 | M32: 6.14 | N32: 6.33
A33: 44378 | B33: 5.59 | C33: 5.82 | D33: 5.49 | E33: 6.13 | F33: 5.74 | G33: 6.59 | H33: 5.11 | I33: 5.89 | J33: 4.63 | K33: 5.53 | L33: 5.82 | M33: 5.93 | N33: 5.46
A34: 44409 | B34: 5.3 | C34: 5.32 | D34: 5.28 | E34: 5.98 | F34: 5.53 | G34: 6.54 | H34: 4.45 | I34: 4.97 | J34: 4.22 | K34: 5.38 | L34: 5.18 | M34: 5.72 | N34: 4.95
A35: 44440 | B35: 4.35 | C35: 4.57 | D35: 4.13 | E35: 6 | F35: 5.54 | G35: 6.57 | H35: 2.42 | I35: 2.91 | J35: 2.14 | K35: 5.46 | L35: 3.15 | M35: 5.89 | N35: 3.21
A36: 44470 | B36: 4.48 | C36: 5.04 | D36: 4.07 | E36: 6.24 | F36: 5.73 | G36: 6.85 | H36: 2.63 | I36: 3.96 | J36: 1.87 | K36: 5.52 | L36: 3.53 | M36: 5.99 | N36: 3.51
A37: 44501 | B37: 4.91 | C37: 5.54 | D37: 4.29 | E37: 6.21 | F37: 5.75 | G37: 6.74 | H37: 3.39 | I37: 5.19 | J37: 2.42 | K37: 5.61 | L37: 4.11 | M37: 6.08 | N37: 4.01
A38: 44531 | B38: 5.66 | C38: 5.9 | D38: 5.36 | E38: 6.12 | F38: 5.65 | G38: 6.73 | H38: 5 | I38: 6.22 | J38: 4.27 | K38: 5.73 | L38: 5.5 | M38: 6.22 | N38: 5.17
A39: 44562 | B39: 6.01 | C39: 5.91 | D39: 6.12 | E39: 6.01 | F39: 5.54 | G39: 6.59 | H39: 5.99 | I39: 6.63 | J39: 5.64 | K39: 5.64 | L39: 6.4 | M39: 6.15 | N39: 5.9
A40: 44593 | B40: 6.07 | C40: 5.75 | D40: 6.38 | E40: 6.02 | F40: 5.53 | G40: 6.63 | H40: 6.27 | I40: 6.29 | J40: 6.18 | K40: 5.77 | L40: 6.5 | M40: 6.29 | N40: 5.99
...

Sheet REER-CPI
A1: Real Effective Exchange Rate Based On Consumer Price Index (CPI) : Base Year 2004-05
A2: Index numbers : 2004-05 to 2022-23
A3: Year | B3: Export weights | C3: Export weights | D3: Export weights | E3: Trade weights | F3: Trade weights | G3: Trade weights | H3: Trade weights | I3: Trade weights | J3: Trade weights | K3: Trade weights | L3: Trade weights | M3: Trade weights | N3: Trade weights
B4: 40 currency | C4: 36 currency | D4: 6 currency | E4: 40 currency | F4: 36 currency | G4: 6 currency | H4: 6 currency | I4: 6 currency | J4: 6 currency | K4: 6 currency | L4: 6 currency | M4: 6 currency | N4: 6 currency
B6: (2015-16 = 100) | C6: (2004-05 = 100) | D6: (2004-05 = 100) | E6: (2015-16 = 100) | F6: (2004-05 = 100) | G6: (2018-19 = 100) | H6: (2015-16 = 100) | I6: (2004-05 = 100) | J6: (2012-13 = 100) | K6: (2013-14 = 100) | L6: (2014-15 = 100) | M6: (2016-17 = 100) | N6: (2021-22 = 100)
A7: Year | B7: Export weights
A8: 2004-05 | B8: 87.4 | C8: 100 | D8: 100 | E8: 89.2 | F8: 100 | I8: 100
A9: 2005-06 | B9: 89.1 | C9: 102 | D9: 104.3 | E9: 91.3 | F9: 102.4 | I9: 104.4
A10: 2006-07 | B10: 87.8 | C10: 100.5 | D10: 104 | E10: 89.9 | F10: 100.8 | I10: 103.8
A11: 2007-08 | B11: 95.4 | C11: 109.2 | D11: 114.6 | E11: 97.4 | F11: 109.2 | I11: 113.4
A12: 2008-09 | B12: 87.1 | C12: 99.7 | D12: 106 | E12: 88.9 | F12: 99.7 | I12: 103.9
A13: 2009-10 | B13: 91.7 | C13: 105 | D13: 113.4 | E13: 92.7 | F13: 103.9 | I13: 110.7
A14: 2010-11 | B14: 100.5 | C14: 115 | D14: 128.5 | E14: 100.5 | F14: 112.7 | I14: 124.5
A15: 2011-12 | B15: 98.9 | C15: 113.2 | D15: 125.8 | E15: 98.4 | F15: 110.3 | I15: 121.2 | J15: 106.3
A16: 2012-13 | B16: 95 | C16: 108.7 | D16: 121.8 | E16: 94.2 | F16: 105.6 | I16: 117.2 | J16: 100 | K16: 103.9
A17: 2013-14 | B17: 92.2 | C17: 105.5 | D17: 117.6 | E17: 92.1 | F17: 103.3 | I17: 112.8 | J17: 96.1 | K17: 100 | L17: 94.1
A18: 2014-15 | B18: 97.2 | C18: 111.3 | E18: 97.2 | F18: 109 | H18: 97.7 | I18: 119.9 | K18: 106.4 | L18: 100
A19: 2015-16 | B19: 100 | C19: 114.4 | E19: 100 | F19: 112.1 | H19: 100 | I19: 122.7 | L19: 103 | M19: 98
A20: 2016-17 | B20: 101.4 | C20: 116.5 | E20: 101.8 | F20: 114.5 | H20: 102.7 | I20: 125.2 | M20: 100
A21: 2017-18 | B21: 105.7 | C21: 121.9 | E21: 105.9 | F21: 119.7 | I21: 129.2 | M21: 103.8
A22: 2018-19 | B22: 100.3 | C22: 116.3 | E22: 100.6 | F22: 114 | G22: 100 | H22: 100.3 | I22: 121.7
A23: 2019-20 | B23: 102.9 | C23: 119.6 | E23: 103.2 | F23: 116.8 | G23: 103.3 | H23: 103.6 | I23: 125.8
A24: 2020-21 | B24: 103 | E24: 103.5 | G24: 101.5 | H24: 101.8
A25: 2021-22 | B25: 103.5 | E25: 104.6 | H25: 102.3 | N25: 100
A26: 2022-23 | B26: 100.9 | E26: 102.7 | H26: 102 | N26: 99.7

Sheet Textile-Apparel-Imports
A1: India's Imports of Major Commodities from World
A2: USD Million : 1991-92 to 2023-24
A3: Year | B3: Non-POL | C3: Non-POL
B4: Manufactured goods | C4: Manufactured goods
A5: Year | B5: Textiles (excluding readymade garments) | C5: Readymade garments
A6: 1991-92 | B6: 158.9
A7: 1992-93 | B7: 167.8
A8: 1993-94 | B8: 254.3
A9: 1994-95 | B9: 371
A10: 1995-96 | B10: 396.6
A11: 1996-97 | B11: 391.4
A12: 1997-98 | B12: 443.8
A13: 1998-99 | B13: 480.8
A14: 1999-00 | B14: 545.7 | C14: 16.1
A15: 2000-01 | B15: 606.7 | C15: 21.4
A16: 2001-02 | B16: 733.8 | C16: 36.2
A17: 2002-03 | B17: 963.4 | C17: 23.9
A18: 2003-04 | B18: 1249.2 | C18: 38.7
A19: 2004-05 | B19: 1562.4 | C19: 33.3
A20: 2005-06 | B20: 2038.5 | C20: 56.8
A21: 2006-07 | B21: 2101.6 | C21: 70.9
A22: 2007-08 | B22: 2378.1 | C22: 111
A23: 2008-09 | B23: 2450.4 | C23: 138.9
A24: 2009-10 | B24: 2475 | C24: 107.6
A25: 2010-11 | B25: 3045 | C25: 197.2
... A37: 2022-23 | B37: 6153.3 | C37: 1756.7
A38: 2023-24

Sheet Textile-Apparel-Exports
A1: India's Exports to Regions and Countries : Textiles (excluding readymade garments)
A2: USD Million : 1991-92 to 2022-23
A3: Year | B3: World | C3: Regions | D3: Regions | E3: Regions | F3: Regions | G3: Regions | H3: Regions | I3: Regions | J3: Countries | K3: Countries | L3: Countries | M3: Countries | N3: Countries | O3: Countries | P3: Countries | Q3: Countries | R3: Countries | S3: Countries | T3: Countries | U3: Countries | V3: Countries | W3: Countries | X3: Countries | Y3: Countries | Z3: Countries | AA3: Countries | AB3: Countries | AC3: Countries | AD3: Countries | AE3: Countries | AF3: Countries | AG3: Countries | AH3: Countries | AI3: Countries | AJ3: Countries | AK3: Countries | AL3: Countries | AM3: Countries | AN3: Countries | AO3: Countries | AP3: Countries | AQ3: Countries | AR3: Countries | AS3: Countries | AT3: Countries | AU3: Countries | AV3: Countries | AW3: Countries | AX3: Countries | AY3: Countries | AZ3: Countries | BA3: Countries | BB3: Countries | BC3: Countries | BD3: Countries | BE3: Countries | BF3: Countries | BG3: Countries | BH3: Countries | BI3: Countries | BJ3: Countries | BK3: Countries | BL3: Countries | BM3: Countries | BN3: Countries | BO3: Countries | BP3: Countries | BQ3: Countries
C4: Africa | D4: America | E4: Europe | F4: Asia | G4: Oceania | H4: Antarctica | I4: Others | J4: USA | K4: Bangladesh | L4: UAE | M4: Turkey | N4: Sri Lanka | O4: UK | P4: Germany | Q4: Italy | R4: China | S4: Egypt | T4: Australia | U4: Netherlands | V4: France | W4: Spain | X4: Korea Republic (South) | Y4: Canada | Z4: Brazil | AA4: Senegal | AB4: Belgium | AC4: Nepal | AD4: Portugal | AE4: Japan | AF4: Vietnam | AG4: Nigeria | AH4: Mexico | AI4: Morocco | AJ4: Peru | AK4: Saudi Arabia | AL4: Indonesia | AM4: Thailand | AN4: South Africa | AO4: Colombia | AP4: Israel | AQ4: Kenya | AR4: Poland | AS4: Malaysia | AT4: Chile | AU4: Sudan (Former) | AV4: Sweden | AW4: Ghana | AX4: Togo | AY4: Denmark | AZ4: Benin | BA4: Argentina | BB4: Guatemala | BC4: Mauritius | BD4: Tanzania | BE4: Ethiopia | BF4: Philippines | BG4: Norway | BH4: New Zealand | BI4: Congo, D.R. | BJ4: Kuwait | BK4: Myanmar (Burma) | BL4: Jordan | BM4: Cote d'Ivoire (Ivory Coast) | BN4: Romania | BO4: Greece | BP4: Russia | BQ4: Afghanistan
A5: 1991-92 | B5: 2512.5 | C5: 106.7 | D5: 449.7 | E5: 1136.3 | F5: 765 | G5: 54.8 | J5: 394 | K5: 143 | L5: 166.8 | M5: 12.1 | N5: 31.1 | O5: 250.7 | P5: 304.8 | Q5: 120.8 | R5: 0.8 | S5: 7.8 | T5: 46 | U5: 29.2 | V5: 67.4 | W5: 31.6 | X5: 67.5 | Y5: 43.4 | Z5: 1.6 | AA5: 0.8 | AB5: 66.2 | AC5: 2.6 | AD5: 7.5 | AE5: 86.6 | AF5: 1.8 | AG5: 6.4 | AH5: 3.5 | AI5: 1.6 | AJ5: 0.1 | AK5: 36.5 | AL5: 8.4 | AM5: 12.3 | AO5: 0.6 | AP5: 3.6 | AQ5: 1.4 | AR5: 2.5 | AS5: 20.7 | AT5: 0.4 | AU5: 0.4 | AV5: 34.2 | AW5: 0.5 | AX5: 5.6 | AY5: 20.8 | AZ5: 9.7 | BA5: 2.3 | BB5: 0.2 | BC5: 30.9 | BD5: 6.3 | BE5: 0.9 | BF5: 3.6 | BG5: 10.9 | BH5: 8.5 | BJ5: 3.6 | BK5: 0.4 | BL5: 1.1 | BM5: 0.3 | BN5: 0.2 | BO5: 6.1 | BP5: 83 | BQ5: 0.6
A6: 1992-93 | B6: 2460.1 | C6: 125.9 | D6: 451.6 | E6: 1106.7 | F6: 704 | G6: 71.7 | J6: 399.1 | K6: 173.3 | L6: 157.2 | M6: 36 | N6: 34.9 | O6: 241.1 | P6: 306.9 | Q6: 114.2 | R6: 1.8 | S6: 10.6 | T6: 59.5 | U6: 31.6 | V6: 69.7 | W6: 32.8 | X6: 20.9 | Y6: 37.6 | Z6: 0.2 | AA6: 1 | AB6: 84.6 | AC6: 2.8 | AD6: 10.2 | AE6: 76.2 | AF6: 2 | AG6: 6.4 | AH6: 4.8 | AI6: 3.2 | AJ6: 0.1 | AK6: 38.4 | AL6: 7.4 | AM6: 6.9 | AN6: 0.1 | AO6: 1 | AP6: 8.3 | AQ6: 3.3 | AR6: 5 | AS6: 20.6 | AT6: 1 | AU6: 0.2 | AV6: 35.6 | AW6: 1 | AX6: 7 | AY6: 23.1 | AZ6: 6.4 | BA6: 1.9 | BB6: 0.4 | BC6: 32.1 | BD6: 5.8 | BE6: 4.7 | BF6: 4.4 | BG6: 11.9 | BH6: 12 | BI6: 0.1 | BJ6: 9.2 | BK6: 0.3 | BL6: 2 | BM6: 0.2 | BN6: 0.4 | BO6: 6.6 | BP6: 19.5 | BQ6: 0.8
A7: 1993-94 | B7: 2882.8 | C7: 146 | D7: 499.3 | E7: 1310.3 | F7: 860.5 | G7: 66.8 | J7: 433.6 | K7: 184.9 | L7: 210.3 | M7: 40.7 | N7: 41.9 | O7: 304.4 | P7: 349 | Q7: 116.3 | R7: 3 | S7: 9.8 | T7: 54.7 | U7: 47 | V7: 71.2 | W7: 29.6 | X7: 28.2 | Y7: 43.8 | Z7: 1.1 | AA7: 0.2 | AB7: 110.7 | AC7: 5.1 | AD7: 17.4 | AE7: 108.5 | AF7: 1.4 | AG7: 7.5 | AH7: 8.1 | AI7: 3.9 | AJ7: 0.2 | AK7: 38.5 | AL7: 5.4 | AM7: 9.3 | AN7: 4.3 | AO7: 0.7 | AP7: 17.5 | AQ7: 14.8 | AR7: 1.5 | AS7: 21.8 | AT7: 3.2 | AU7: 0.4 | AV7: 36.1 | AW7: 1.1 | AX7: 4.6 | AY7: 23.7 | AZ7: 5.4 | BA7: 2.6 | BB7: 0.4 | BC7: 49.3 | BD7: 4.7 | BE7: 1.5 | BF7: 5.1 | BG7: 13.4 | BH7: 11.9 | BI7: 0 | BJ7: 10.1 | BK7: 0.2 | BL7: 4.7 | BM7: 0.1 | BN7: 0.2 | BO7: 8.4 | BP7: 32.6 | BQ7: 0.4
A8: 1994-95 | B8: 3836.8 | C8: 224.4 | D8: 613 | E8: 1605 | F8: 1296.7 | G8: 97.7 | J8: 530.9 | K8: 268.7 | L8: 259.7 | M8: 41 | N8: 64 | O8: 381 | P8: 345.2 | Q8: 177 | R8: 11.2 | S8: 17.4 | T8: 78.1 | U8: 65 | V8: 92.3 | W8: 53.7 | X8: 95 | Y8: 49.3 | Z8: 5.3 | AA8: 0.9 | AB8: 163.1 | AC8: 4.5 | AD8: 21.8 | AE8: 157.6 | AF8: 3.8 | AG8: 8.8 | AH8: 8 | AI8: 4.4 | AJ8: 0.4 | AK8: 44.1 | AL8: 9.2 | AM8: 13.5 | AN8: 34.8 | AO8: 0.8 | AP8: 24.6 | AQ8: 18 | AR8: 1.9 | AS8: 38 | AT8: 4.8 | AU8: 1.1 | AV8: 42.9 | AW8: 1.1 | AX8: 10.4 | AY8: 30.6 | AZ8: 5.5 | BA8: 3.5 | BB8: 1.6 | BC8: 73.6 | BD8: 4.7 | BE8: 1.2 | BF8: 12 | BG8: 18.4 | BH8: 19.3 | BI8: 0.1 | BJ8: 11.5 | BK8: 0.1 | BL8: 5.1 | BM8: 0.6 | BN8: 0.4 | BO8: 10.2 | BP8: 67 | BQ8: 0.5
A9: 1995-96 | B9: 4361.2 | C9: 324.5 | D9: 698.2 | E9: 1797.1 | F9: 1446.7 | G9: 94.7 | J9: 602.5 | K9: 292 | L9: 262.7 | M9: 67.6 | N9: 64.2 | O9: 405.5 | P9: 382.4 | Q9: 210.6 | R9: 22.9 | S9: 26.3 | T9: 76.6 | U9: 69.2 | V9: 103.7 | W9: 70.6 | X9: 110.8 | Y9: 51.6 | Z9: 10.4 | AA9: 5.7 | AB9: 163.8 | AC9: 9.7 | AD9: 32.4 | AE9: 145 | AF9: 4.3 | AG9: 22.2 | AH9: 4.8 | AI9: 5.5 | AJ9: 0.4 | AK9: 63.1 | AL9: 11.8 | AM9: 15.9 | AN9: 42.2 | AO9: 2.8 | AP9: 39.2 | AQ9: 16.6 | AR9: 2.3 | AS9: 39.3 | AT9: 8 | AU9: 2.9 | AV9: 47.2 | AW9: 1.6 | AX9: 10.3 | AY9: 34.4 | AZ9: 5.9 | BA9: 4.4 | BB9: 1.1 | BC9: 92.5 | BD9: 10.9 | BE9: 1.6 | BF9: 11.5 | BG9: 18.5 | BH9: 17.7 | BJ9: 16.8 | BK9: 0.1 | BL9: 7.2 | BM9: 0.6 | BN9: 0.2 | BO9: 15.4 | BP9: 75 | BQ9: 1.7
A10: 1996-97 | B10: 4885.3 | C10: 386.4 | D10: 897.3 | E10: 1799.5 | F10: 1708.6 | G10: 93.5 | J10: 751.5 | K10: 355.6 | L10: 233.9 | M10: 60.3 | N10: 67.7 | O10: 415.9 | P10: 378.7 | Q10: 181.2 | R10: 48.4 | S10: 43.1 | T10: 75 | U10: 60.5 | V10: 98.4 | W10: 77.7 | X10: 130.3 | Y10: 69 | Z10: 18 | AA10: 4.6 | AB10: 158.1 | AC10: 13.7 | AD10: 32.8 | AE10: 150.9 | AF10: 6.8 | AG10: 12.4 | AH10: 7.5 | AI10: 7.2 | AJ10: 0.3 | AK10: 59.8 | AL10: 18.2 | AM10: 17.5 | AN10: 51.5 | AO10: 12.2 | AP10: 36.4 | AQ10: 24.5 | AR10: 5.6 | AS10: 45.9 | AT10: 13.8 | AU10: 1.7 | AV10: 54.8 | AW10: 4.6 | AX10: 20.8 | AY10: 34.5 | AZ10: 13.2 | BA10: 8.3 | BB10: 1.5 | BC10: 101.5 | BD10: 9.7 | BE10: 2.7 | BF10: 10.5 | BG10: 21.7 | BH10: 17.3 | BJ10: 18.4 | BK10: 0.1 | BL10: 7.3 | BM10: 3.3 | BN10: 0.4 | BO10: 17.8 | BP10: 83.9 | BQ10: 2
A11: 1997-98 | B11: 5179.1 | C11: 467.5 | D11: 942.1 | E11: 1886.2 | F11: 1783.9 | G11: 99.4 | J11: 746.9 | K11: 291.9 | L11: 260.8 | M11: 91.3 | N11: 77.4 | O11: 404 | P11: 336.9 | Q11: 246.4 | R11: 59.1 | S11: 69.2 | T11: 81.1 | U11: 66.9 | V11: 106.9 | W11: 89.8 | X11: 127 | Y11: 88.8 | Z11: 21.1 | AA11: 6.3 | AB11: 163.7 | AC11: 12.4 | AD11: 34.9 | AE11: 180.5 | AF11: 6.1 | AG11: 10.9 | AH11: 15.1 | AI11: 8.5 | AJ11: 0.7 | AK11: 77.2 | AL11: 20.7 | AM11: 18.2 | AN11: 67.8 | AO11: 13.6 | AP11: 63.6 | AQ11: 20.2 | AR11: 10.2 | AS11: 41.9 | AT11: 21.9 | AU11: 4.3 | AV11: 55.9 | AW11: 10.9 | AX11: 19.7 | AY11: 39.1 | AZ11: 14.7 | BA11: 9.5 | BB11: 1.8 | BC11: 114.9 | BD11: 12 | BE11: 3.6 | BF11: 11 | BG11: 17.7 | BH11: 17.2 | BI11: 2.4 | BJ11: 18.6 | BK11: 0.4 | BL11: 7.9 | BM11: 4.5 | BN11: 0.5 | BO11: 17.6 | BP11: 85.5 | BQ11: 1.7
A12: 1998-99 | B12: 4496.1 | C12: 436.6 | D12: 938.6 | E12: 1640.9 | F12: 1392.2 | G12: 87.8 | J12: 759.6 | K12: 138.2 | L12: 237.1 | M12: 47.7 | N12: 84.6 | O12: 338.3 | P12: 301.7 | Q12: 236.2 | R12: 44.9 | S12: 71.2 | T12: 72.2 | U12: 58.6 | V12: 105.2 | W12: 93.1 | X12: 88.2 | Y12: 85.9 | Z12: 17.7 | AA12: 7.1 | AB12: 129.1 | AC12: 6.7 | AD12: 37.8 | AE12: 115.5 | AF12: 7.5 | AG12: 21.2 | AH12: 8.9 | AI12: 7.2 | AJ12: 1.6 | AK12: 68.8 | AL12: 15.3 | AM12: 22.1 | AN12: 45.9 | AO12: 11.2 | AP12: 64.1 | AQ12: 19.4 | AR12: 12.8 | AS12: 33.4 | AT12: 15.6 | AU12: 7.9 | AV12: 46.9 | AW12: 12.6 | AX12: 13.9 | AY12: 38.7 | AZ12: 14.6 | BA12: 10 | BB12: 1.4 | BC12: 99.9 | BD12: 15.8 | BE12: 2.7 | BF12: 7.6 | BG12: 13.3 | BH12: 11.9 | BI12: 4 | BJ12: 20.9 | BK12: 2 | BL12: 10.2 | BM12: 8 | BN12: 1.3 | BO12: 15.3 | BP12: 56.5 | BQ12: 2.1
A13: 1999-00 | B13: 5056.1 | C13: 482.8 | D13: 1085.4 | E13: 1721.4 | F13: 1673.3 | G13: 93.3 | J13: 886.3 | K13: 173.9 | L13: 269.4 | M13: 65.8 | N13: 98.5 | O13: 327.1 | P13: 329.2 | Q13: 215.7 | R13: 60.7 | S13: 68.4 | T13: 76.1 | U13: 60.8 | V13: 118.8 | W13: 99.6 | X13: 199.9 | Y13: 93.9 | Z13: 14.7 | AA13: 7 | AB13: 137.6 | AC13: 5.3 | AD13: 42.6 | AE13: 139 | AF13: 5.6 | AG13: 44.3 | AH13: 10.2 | AI13: 6 | AJ13: 1.9 | AK13: 70.9 | AL13: 32.2 | AM13: 37.8 | AN13: 38.8 | AO13: 12.6 | AP13: 65.5 | AQ13: 20.6 | AR13: 15.7 | AS13: 48.4 | AT13: 13.8 | AU13: 11.6 | AV13: 47.8 | AW13: 13.5 | AX13: 12.4 | AY13: 39.5 | AZ13: 18.1 | BA13: 9.2 | BB13: 2.8 | BC13: 105.8 | BD13: 15.7 | BE13: 3.4 | BF13: 12.2 | BG13: 15.7 | BH13: 12.9 | BI13: 8 | BJ13: 16.4 | BK13: 1.8 | BL13: 5.1 | BM13: 15.5 | BN13: 1.3 | BO13: 19.5 | BP13: 77.5 | BQ13: 2.5
A14: 2000-01 | B14: 5714.1 | C14: 606.9 | D14: 1254 | E14: 1886.1 | F14: 1878.9 | G14: 87.5 | I14: 0.8 | J14: 1003.1 | K14: 201.4 | L14: 296.1 | M14: 120.7 | N14: 105.5 | O14: 331.1 | P14: 316.1 | Q14: 260.5 | R14: 79.4 | S14: 86.4 | T14: 72.6 | U14: 58.4 | V14: 128.4 | W14: 126.5 | X14: 142 | Y14: 97.4 | Z14: 17.9 | AA14: 8.8 | AB14: 157 | AC14: 13.4 | AD14: 53.6 | AE14: 152 | AF14: 9.2 | AG14: 44 | AH14: 13 | AI14: 13.3 | AJ14: 2.8 | AK14: 81 | AL14: 42.2 | AM14: 33 | AN14: 52.5 | AO14: 19.9 | AP14: 74.4 | AQ14: 17 | AR14: 16.9 | AS14: 53.4 | AT14: 20.3 | AU14: 15.6 | AV14: 49.1 | AW14: 12.6 | AX14: 26 | AY14: 25.9 | AZ14: 21.3 | BA14: 13.8 | BB14: 4.5 | BC14: 118 | BD14: 28.3 | BE14: 2.8 | BF14: 15.5 | BG14: 16.2 | BH14: 11.9 | BI14: 13.9 | BJ14: 16.4 | BK14: 1 | BL14: 8 | BM14: 26.9 | BN14: 2.1 | BO14: 26.6 | BP14: 74.8 | BQ14: 5.2
A15: 2001-02 | B15: 5200 | C15: 607 | D15: 1102.9 | E15: 1612.4 | F15: 1792.1 | G15: 84.3 | I15: 1.4 | J15: 886 | K15: 183.3 | L15: 315.2 | M15: 74.1 | N15: 97.5 | O15: 304.9 | P15: 249 | Q15: 241.7 | R15: 80.9 | S15: 70.1 | T15: 70.3 | U15: 47.6 | V15: 111.4 | W15: 134.9 | X15: 141.5 | Y15: 86.7 | Z15: 16.1 | AA15: 6.6 | AB15: 122.4 | AC15: 9.8 | AD15: 53.9 | AE15: 145.8 | AF15: 5.3 | AG15: 57.7 | AH15: 15.3 | AI15: 26 | AJ15: 4.9 | AK15: 82.2 | AL15: 51.6 | AM15: 22.9 | AN15: 45 | AO15: 18.4 | AP15: 53.8 | AQ15: 20.2 | AR15: 17.2 | AS15: 79.3 | AT15: 13.7 | AU15: 10.3 | AV15: 44.1 | AW15: 11.3 | AX15: 39.2 | AY15: 22.7 | AZ15: 31.7 | BA15: 7.2 | BB15: 2.5 | BC15: 92.8 | BD15: 21.8 | BE15: 3.2 | BF15: 14.2 | BG15: 13.3 | BH15: 10.9 | BI15: 13.2 | BJ15: 23.5 | BK15: 0.6 | BL15: 8.9 | BM15: 23.5 | BN15: 0.8 | BO15: 23.7 | BP15: 36.6 | BQ15: 5.8
A16: 2002-03 | B16: 5925.3 | C16: 644.3 | D16: 1384.6 | E16: 1742.9 | F16: 2042.7 | G16: 103.9 | I16: 6.9 | J16: 1131.9 | K16: 167.8 | L16: 396.4 | M16: 138.9 | N16: 115.2 | O16: 300.2 | P16: 261.5 | Q16: 251.5 | R16: 76.1 | S16: 83.9 | T16: 88.2 | U16: 54.1 | V16: 112.9 | W16: 158.8 | X16: 195.5 | Y16: 106.8 | Z16: 23.4 | AA16: 8.3 | AB16: 126.5 | AC16: 11.5 | AD16: 62 | AE16: 157.4 | AF16: 9.7 | AG16: 51.2 | AH16: 16 | AI16: 37 | AJ16: 6.5 | AK16: 112.5 | AL16: 44.8 | AM16: 19.5 | AN16: 45.2 | AO16: 20.1 | AP16: 68.7 | AQ16: 24.3 | AR16: 22.2 | AS16: 69.1 | AT16: 15.3 | AU16: 6.2 | AV16: 44.4 | AW16: 21.1 | AX16: 44 | AY16: 24.5 | AZ16: 30.3 | BA16: 2.6 | BB16: 3 | BC16: 88 | BD16: 24.2 | BE16: 2.9 | BF16: 17.6 | BG16: 12.6 | BH16: 11.6 | BI16: 10.6 | BJ16: 23.9 | BK16: 0.5 | BL16: 10.2 | BM16: 16.9 | BN16: 1 | BO16: 26.6 | BP16: 18.3 | BQ16: 9.9
A17: 2003-04 | B17: 6564.5 | C17: 684.3 | D17: 1381.9 | E17: 2038.3 | F17: 2345.6 | G17: 101 | I17: 13.4 | J17: 1154.1 | K17: 207.2 | L17: 476 | M17: 207.1 | N17: 139.1 | O17: 346.5 | P17: 305.1 | Q17: 291.4 | R17: 97.3 | S17: 106.7 | T17: 83.1 | U17: 61.4 | V17: 134 | W17: 169.8 | X17: 227.7 | Y17: 100 | Z17: 23.1 | AA17: 6.2 | AB17: 120.7 | AC17: 39.2 | AD17: 68.4 | AE17: 149.2 | AF17: 12.5 | AG17: 49.2 | AH17: 14.8 | AI17: 41.8 | AJ17: 4.9 | AK17: 142.5 | AL17: 67.3 | AM17: 24.2 | AN17: 54.2 | AO17: 16.8 | AP17: 58 | AQ17: 25.1 | AR17: 28.2 | AS17: 81.3 | AT17: 15 | AU17: 4.8 | AV17: 51.6 | AW17: 28.5 | AX17: 34.5 | AY17: 26.3 | AZ17: 25.2 | BA17: 7.3 | BB17: 4.1 | BC17: 98.9 | BD17: 17.1 | BE17: 2.2 | BF17: 17.9 | BG17: 14.9 | BH17: 13.3 | BI17: 16.6 | BJ17: 32.7 | BK17: 0.3 | BL17: 11 | BM17: 13.4 | BN17: 3 | BO17: 37.6 | BP17: 21.4 | BQ17: 21.3
A18: 2004-05 | B18: 6991 | C18: 716.4 | D18: 1558.9 | E18: 2160.2 | F18: 2443.8 | G18: 105.1 | I18: 6.6 | J18: 1262.2 | K18: 252.8 | L18: 565.1 | M18: 224.2 | N18: 139.2 | O18: 344.3 | P18: 336.5 | Q18: 338.1 | R18: 93.1 | S18: 129.5 | T18: 86.4 | U18: 67 | V18: 150.3 | W18: 175.6 | X18: 186.2 | Y18: 101.3 | Z18: 54.6 | AA18: 6.9 | AB18: 141.6 | AC18: 23.4 | AD18: 65.1 | AE18: 128.1 | AF18: 17.7 | AG18: 25.8 | AH18: 16.9 | AI18: 40.1 | AJ18: 17.4 | AK18: 154.6 | AL18: 66.3 | AM18: 23.2 | AN18: 64.5 | AO18: 21 | AP18: 66.5 | AQ18: 30.8 | AR18: 30.1 | AS18: 108.6 | AT18: 19.5 | AU18: 11.8 | AV18: 50.1 | AW18: 29 | AX18: 28.6 | AY18: 29.8 | AZ18: 24.6 | BA18: 11.8 | BB18: 7.3 | BC18: 79.2 | BD18: 17.3 | BE18: 1.6 | BF18: 19.5 | BG18: 17.8 | BH18: 14.4 | BI18: 21.5 | BJ18: 30.5 | BK18: 1.2 | BL18: 7.8 | BM18: 5.1 | BN18: 6.6 | BO18: 38.6 | BP18: 17.4 | BQ18: 46
A19: 2005-06 | B19: 7783.2 | C19: 708.1 | D19: 1991.6 | E19: 2475.4 | F19: 2490.9 | G19: 112.8 | I19: 4.4 | J19: 1632.8 | K19: 310.9 | L19: 520 | M19: 233.9 | N19: 174.1 | O19: 356.3 | P19: 414.2 | Q19: 392.8 | R19: 117.5 | S19: 164.7 | T19: 92.1 | U19: 81.7 | V19: 152.4 | W19: 197.9 | X19: 232.1 | Y19: 118.6 | Z19: 69.1 | AA19: 12.3 | AB19: 153.7 | AC19: 22.2 | AD19: 90 | AE19: 137.4 | AF19: 17.9 | AG19: 11.8 | AH19: 19.9 | AI19: 42.3 | AJ19: 20.9 | AK19: 150.9 | AL19: 43.7 | AM19: 30.7 | AN19: 68.7 | AO19: 24.2 | AP19: 74.2 | AQ19: 32.8 | AR19: 40.6 | AS19: 81.4 | AT19: 27 | AU19: 18 | AV19: 68.9 | AW19: 18.2 | AX19: 30.7 | AY19: 35.6 | AZ19: 24 | BA19: 19.2 | BB19: 11.8 | BC19: 63.5 | BD19: 24.5 | BE19: 2.3 | BF19: 21.2 | BG19: 24.7 | BH19: 14.8 | BI19: 22.5 | BJ19: 29 | BK19: 0.5 | BL19: 9 | BM19: 9.6 | BN19: 8.1 | BO19: 48.3 | BP19: 35 | BQ19: 28.7
A20: 2006-07 | B20: 8475.2 | C20: 920.2 | D20: 2176.6 | E20: 2725 | F20: 2538.4 | G20: 111.5 | I20: 3.5 | J20: 1640.6 | K20: 292 | L20: 512.2 | M20: 307.2 | N20: 191 | O20: 389.4 | P20: 424.2 | Q20: 421.2 | R20: 137.5 | S20: 207.5 | T20: 88.4 | U20: 88.9 | V20: 146.4 | W20: 206.3 | X20: 223.8 | Y20: 113.5 | Z20: 122.2 | AA20: 35.4 | AB20: 178.6 | AC20: 22.2 | AD20: 125.4 | AE20: 149.3 | AF20: 22 | AG20: 39.6 | AH20: 34.1 | AI20: 64.1 | AJ20: 39 | AK20: 156.1 | AL20: 69.8 | AM20: 33.1 | AN20: 74.1 | AO20: 48.9 | AP20: 81.9 | AQ20: 37 | AR20: 51.5 | AS20: 77.8 | AT20: 27.2 | AU20: 43.2 | AV20: 67.3 | AW20: 29.9 | AX20: 45.9 | AY20: 32.5 | AZ20: 35.7 | BA20: 28.6 | BB20: 13.5 | BC20: 73.3 | BD20: 41.3 | BE20: 2 | BF20: 31.8 | BG20: 27.3 | BH20: 15.1 | BI20: 18.4 | BJ20: 24.4 | BK20: 1.5 | BL20: 9.3 | BM20: 5.8 | BN20: 12.8 | BO20: 51.4 | BP20: 40.2 | BQ20: 34.4
A21: 2007-08 | B21: 9743.6 | C21: 1140.5 | D21: 2418.3 | E21: 3108.6 | F21: 2951.2 | G21: 120.1 | I21: 4.7 | J21: 1655.8 | K21: 434.8 | L21: 632.7 | M21: 512.6 | N21: 224 | O21: 417.2 | P21: 485.1 | Q21: 412.3 | R21: 119.8 | S21: 251.6 | T21: 94.5 | U21: 98.2 | V21: 162 | W21: 196.6 | X21: 187.8 | Y21: 119.8 | Z21: 247.9 | AA21: 73.4 | AB21: 200.2 | AC21: 83.1 | AD21: 138.9 | AE21: 129.3 | AF21: 36.2 | AG21: 28 | AH21: 43.5 | AI21: 73.2 | AJ21: 97.3 | AK21: 154.6 | AL21: 71.8 | AM21: 33.1 | AN21: 71.3 | AO21: 55.5 | AP21: 69.7 | AQ21: 49.3 | AR21: 55.6 | AS21: 72.7 | AT21: 31.8 | AU21: 44.2 | AV21: 60.3 | AW21: 30.8 | AX21: 59.9 | AY21: 34.2 | AZ21: 75.6 | BA21: 49.5 | BB21: 12.8 | BC21: 73 | BD21: 50.5 | BE21: 4.5 | BF21: 23.7 | BG21: 25.7 | BH21: 19.1 | BI21: 22.5 | BJ21: 24.9 | BK21: 4 | BL21: 9.3 | BM21: 5.7 | BN21: 12.5 | BO21: 61.2 | BP21: 54.4 | BQ21: 78.6
A22: 2008-09 | B22: 9095.9 | C22: 1034.8 | D22: 2206.1 | E22: 2520.4 | F22: 3200.6 | G22: 127 | I22: 7.1 | J22: 1487.4 | K22: 412.7 | L22: 662.9 | M22: 293.2 | N22: 254 | O22: 370.8 | P22: 464.8 | Q22: 324.9 | R22: 148.7 | S22: 234.6 | T22: 104.5 | U22: 100.4 | V22: 129.4 | W22: 134.3 | X22: 150.6 | Y22: 100.1 | Z22: 250.3 | AA22: 53.6 | AB22: 170.7 | AC22: 46.1 | AD22: 111.4 | AE22: 120.7 | AF22: 42.4 | AG22: 33 | AH22: 53.6 | AI22: 60.4 | AJ22: 78.4 | AK22: 179.3 | AL22: 65.9 | AM22: 40.2 | AN22: 61.8 | AO22: 60.6 | AP22: 58.4 | AQ22: 60.7 | AR22: 50.7 | AS22: 59.8 | AT22: 33.7 | AU22: 40.5 | AV22: 51.5 | AW22: 32.8 | AX22: 55.4 | AY22: 33.8 | AZ22: 63.4 | BA22: 45.1 | BB22: 14.7 | BC22: 48 | BD22: 62.6 | BE22: 3.5 | BF22: 20.5 | BG22: 22.3 | BH22: 15.6 | BI22: 0 | BJ22: 23.7 | BK22: 5.5 | BL22: 10 | BM22: 10.3 | BN22: 17.3 | BO22: 43.9 | BP22: 50.3 | BQ22: 141.6
A23: 2009-10 | B23: 9151.9 | C23: 1081.8 | D23: 1987.6 | E23: 2311.6 | F23: 3660.1 | G23: 98.6 | I23: 12.1 | J23: 1212.9 | K23: 400.3 | L23: 639.3 | M23: 378.2 | N23: 276 | O23: 311.4 | P23: 416.4 | Q23: 265.3 | R23: 218.6 | S23: 207.9 | T23: 82.1 | U23: 86.6 | V23: 110.8 | W23: 109.3 | X23: 241 | Y23: 83.2 | Z23: 322.1 | AA23: 66.1 | AB23: 156.4 | AC23: 61.7 | AD23: 113.1 | AE23: 80.2 | AF23: 64.4 | AG23: 31.4 | AH23: 55.3 | AI23: 68.3 | AJ23: 89.9 | AK23: 152.8 | AL23: 62.9 | AM23: 41.1 | AN23: 74.1 | AO23: 72.6 | AP23: 60.9 | AQ23: 62.1 | AR23: 53.5 | AS23: 71 | AT23: 27.7 | AU23: 32.7 | AV23: 39.2 | AW23: 22.7 | AX23: 64.7 | AY23: 30.1 | AZ23: 77.1 | BA23: 34.5 | BB23: 21.6 | BC23: 41.1 | BD23: 60.6 | BE23: 3.3 | BF23: 33.9 | BG23: 21.4 | BH23: 12 | BI23: 0.4 | BJ23: 25.5 | BK23: 8.2 | BL23: 10.8 | BM23: 23.9 | BN23: 20.3 | BO23: 37.8 | BP23: 53.1 | BQ23: 227.5
A24: 2010-11 | B24: 12621.1 | C24: 1392 | D24: 2947.7 | E24: 3117.8 | F24: 5014.8 | G24: 130.3 | I24: 18.6 | J24: 1749.9 | K24: 786.1 | L24: 764 | M24: 572.6 | N24: 376 | O24: 385.2 | P24: 525.1 | Q24: 364.9 | R24: 443.8 | S24: 334.6 | T24: 108.6 | U24: 129.1 | V24: 115.6 | W24: 170.2 | X24: 347 | Y24: 100.7 | Z24: 472.2 | AA24: 63.6 | AB24: 206 | AC24: 66.1 | AD24: 200.4 | AE24: 138.1 | AF24: 97.8 | AG24: 55.1 | AH24: 92 | AI24: 98 | AJ24: 135.2 | AK24: 192.2 | AL24: 116.3 | AM24: 59.1 | AN24: 96.3 | AO24: 123 | AP24: 66.1 | AQ24: 64.8 | AR24: 94 | AS24: 190.4 | AT24: 53.4 | AU24: 37.3 | AV24: 46.4 | AW24: 32.9 | AX24: 90.4 | AY24: 38.4 | AZ24: 65.6 | BA24: 62 | BB24: 34.9 | BC24: 66.3 | BD24: 64.7 | BE24: 6 | BF24: 40.9 | BG24: 33 | BH24: 16.3 | BI24: 0.3 | BJ24: 24.2 | BK24: 9.4 | BL24: 11.2 | BM24: 12.9 | BN24: 23.7 | BO24: 29.5 | BP24: 39.5 | BQ24: 183.4
A25: 2011-12 | B25: 14327.3 | C25: 1977.2 | D25: 3448.6 | E25: 3465.7 | F25: 5257.7 | G25: 173.8 | I25: 4.3 | J25: 2086 | K25: 810.5 | L25: 746.7 | M25: 616.6 | N25: 418.3 | O25: 469 | P25: 595.3 | Q25: 402.8 | R25: 726.9 | S25: 559 | T25: 148 | U25: 151.8 | V25: 148.2 | W25: 184.9 | X25: 261.8 | Y25: 145.3 | Z25: 404.7 | AA25: 65.4 | AB25: 219.1 | AC25: 77.8 | AD25: 178 | AE25: 161.3 | AF25: 119.1 | AG25: 82.2 | AH25: 115.8 | AI25: 123.6 | AJ25: 179.4 | AK25: 233 | AL25: 138 | AM25: 120.3 | AN25: 113.7 | AO25: 178.6 | AP25: 64.7 | AQ25: 81.5 | AR25: 97.7 | AS25: 145.4 | AT25: 62.7 | AU25: 44.5 | AV25: 63.1 | AW25: 48.9 | AX25: 158.3 | AY25: 43.8 | AZ25: 85.8 | BA25: 68.6 | BB25: 38.5 | BC25: 60.7 | BD25: 75.3 | BE25: 12.3 | BF25: 34.8 | BG25: 37.7 | BH25: 19.4 | BI25: 0 | BJ25: 35.2 | BK25: 11.2 | BL25: 20 | BM25: 25.3 | BN25: 27.3 | BO25: 24 | BP25: 30.5 | BQ25: 136.7
A26: 2012-13 | B26: 14424 | C26: 1592 | D26: 3607.5 | E26: 3189.1 | F26: 5860 | G26: 172.6 | I26: 2.7 | J26: 2296.2 | K26: 1103.5 | L26: 640.2 | M26: 601.6 | N26: 395.8 | O26: 490 | P26: 497.4 | Q26: 309.7 | R26: 1291.6 | S26: 401.2 | T26: 146.6 | U26: 135.1 | V26: 129.9 | W26: 157.2 | X26: 244.9 | Y26: 139.4 | Z26: 384.3 | AA26: 77.6 | AB26: 183.3 | AC26: 77.2 | AD26: 190 | AE26: 138.2 | AF26: 125.7 | AG26: 77.2 | AH26: 114.3 | AI26: 117.8 | AJ26: 174.1 | AK26: 188.8 | AL26: 166 | AM26: 139.3 | AN26: 102.8 | AO26: 159.5 | AP26: 51.3 | AQ26: 70.6 | AR26: 88.4 | AS26: 144 | AT26: 68.6 | AU26: 59.6 | AV26: 55.9 | AW26: 46.1 | AX26: 111.7 | AY26: 41.5 | AZ26: 50.4 | BA26: 72.4 | BB26: 52.3 | BC26: 55.5 | BD26: 46.5 | BE26: 15 | BF26: 48.8 | BG26: 35.9 | BH26: 19.4 | BI26: 6.1 | BJ26: 33.8 | BK26: 17.8 | BL26: 27.3 | BM26: 21.9 | BN26: 25.8 | BO26: 19.2 | BP26: 54.7 | BQ26: 148.2
A27: 2013-14 | B27: 17993.8 | C27: 1853.1 | D27: 4417.5 | E27: 3921 | F27: 7484.3 | G27: 225.7 | H27: 0 | I27: 92.2 | J27: 3032.6 | K27: 1188.2 | L27: 862 | M27: 730.8 | N27: 501.1 | O27: 576.2 | P27: 583.6 | Q27: 387.5 | R27: 2099.8 | S27: 390.8 | T27: 187.9 | U27: 181 | V27: 187.7 | W27: 206 | X27: 279.3 | Y27: 193.2 | Z27: 397.6 | AA27: 79.5 | AB27: 212 | AC27: 87.2 | AD27: 213.1 | AE27: 179.2 | AF27: 211.2 | AG27: 101.7 | AH27: 108.1 | AI27: 121.9 | AJ27: 186.6 | AK27: 128.5 | AL27: 145.4 | AM27: 130.7 | AN27: 115.2 | AO27: 164.9 | AP27: 76.5 | AQ27: 90.6 | AR27: 117.3 | AS27: 158.1 | AT27: 71.7 | AU27: 63.7 | AV27: 70.9 | AW27: 58 | AX27: 154.5 | AY27: 57.9 | AZ27: 76.9 | BA27: 70.5 | BB27: 41.6 | BC27: 66.6 | BD27: 44.8 | BE27: 22.1 | BF27: 50 | BG27: 48.4 | BH27: 29.3 | BI27: 12.8 | BJ27: 37 | BK27: 46.3 | BL27: 41.3 | BM27: 21.3 | BN27: 22.6 | BO27: 23.2 | BP27: 67.3 | BQ27: 204.1
A28: 2014-15 | B28: 18020.4 | C28: 1872 | D28: 4720.6 | E28: 3838.4 | F28: 7344.5 | G28: 244.4 | I28: 0.5 | J28: 3361.5 | K28: 1338.9 | L28: 1046.4 | M28: 630 | N28: 490.3 | O28: 598.4 | P28: 566.9 | Q28: 383.2 | R28: 1772 | S28: 418.3 | T28: 201 | U28: 195 | V28: 193.5 | W28: 216.2 | X28: 314.2 | Y28: 193.1 | Z28: 309.3 | AA28: 86.5 | AB28: 230.1 | AC28: 96.2 | AD28: 185.5 | AE28: 185.2 | AF28: 295.1 | AG28: 108.6 | AH28: 125.9 | AI28: 85.9 | AJ28: 196.6 | AK28: 115.4 | AL28: 137 | AM28: 93.1 | AN28: 102.8 | AO28: 172.3 | AP28: 77.9 | AQ28: 90.7 | AR28: 108.8 | AS28: 131.7 | AT28: 69.9 | AU28: 77.6 | AV28: 85.7 | AW28: 52.4 | AX28: 151.9 | AY28: 65.2 | AZ28: 68 | BA28: 55.5 | BB28: 53.3 | BC28: 59.7 | BD28: 58.9 | BE28: 20.1 | BF28: 48.2 | BG28: 49.7 | BH28: 35.1 | BI28: 21.3 | BJ28: 43.7 | BK28: 49.9 | BL28: 26.9 | BM28: 23.6 | BN28: 12.8 | BO28: 24.7 | BP28: 59.7 | BQ28: 166
A29: 2015-16 | B29: 16656.9 | C29: 1641.1 | D29: 4495.2 | E29: 3467.4 | F29: 6807.8 | G29: 245.1 | I29: 0.3 | J29: 3404.2 | K29: 1344 | L29: 888.8 | M29: 541.5 | N29: 485.2 | O29: 564.4 | P29: 537.1 | Q29: 353.7 | R29: 1683.5 | S29: 348.8 | T29: 205.6 | U29: 173.4 | V29: 180.5 | W29: 209.6 | X29: 300.1 | Y29: 186.2 | Z29: 174 | AA29: 82.3 | AB29: 188.8 | AC29: 105 | AD29: 177.2 | AE29: 167 | AF29: 190.5 | AG29: 102.6 | AH29: 135.3 | AI29: 82.2 | AJ29: 152.6 | AK29: 105.9 | AL29: 123.6 | AM29: 103.5 | AN29: 104.9 | AO29: 139.7 | AP29: 77.3 | AQ29: 81.4 | AR29: 101.4 | AS29: 116.2 | AT29: 71 | AU29: 72.1 | AV29: 71.2 | AW29: 58.6 | AX29: 127.6 | AY29: 60.3 | AZ29: 68.4 | BA29: 64.3 | BB29: 46.4 | BC29: 57.9 | BD29: 45.4 | BE29: 19.6 | BF29: 36.9 | BG29: 38.3 | BH29: 31.3 | BI29: 19.3 | BJ29: 41.1 | BK29: 57.2 | BL29: 22.8 | BM29: 29.5 | BN29: 15.6 | BO29: 24.6 | BP29: 44.6 | BQ29: 116.8
A30: 2016-17 | B30: 16402 | C30: 1477 | D30: 4704.6 | E30: 3603.9 | F30: 6358.8 | G30: 256.8 | I30: 0.9 | J30: 3471.4 | K30: 1373.8 | L30: 683.7 | M30: 540.8 | N30: 495.4 | O30: 523.9 | P30: 566.3 | Q30: 373.6 | R30: 1303.1 | S30: 290.5 | T30: 213.9 | U30: 221.5 | V30: 188 | W30: 215.7 | X30: 317.8 | Y30: 202.7 | Z30: 313.7 | AA30: 104.7 | AB30: 186.4 | AC30: 110.9 | AD30: 194 | AE30: 165.8 | AF30: 198.9 | AG30: 74 | AH30: 128.4 | AI30: 85.8 | AJ30: 160.9 | AK30: 109.8 | AL30: 128.3 | AM30: 119.9 | AN30: 97.6 | AO30: 146.4 | AP30: 88.1 | AQ30: 79.7 | AR30: 115.7 | AS30: 105.6 | AT30: 70.7 | AU30: 84.8 | AV30: 76.7 | AW30: 54 | AX30: 91.2 | AY30: 59.2 | AZ30: 51 | BA30: 51.1 | BB30: 44.2 | BC30: 58 | BD30: 45.4 | BE30: 22.7 | BF30: 43.9 | BG30: 39.7 | BH30: 33.2 | BI30: 14.9 | BJ30: 38.7 | BK30: 51.4 | BL30: 19.8 | BM30: 20.9 | BN30: 15.4 | BO30: 26.6 | BP30: 56.6 | BQ30: 89.7
A31: 2017-18 | B31: 17078.4 | C31: 1653.8 | D31: 4971.8 | E31: 3918.4 | F31: 6252.8 | G31: 281.3 | H31: 0.1 | I31: 0 | J31: 3563.4 | K31: 1519.4 | L31: 498.7 | M31: 708.2 | N31: 496.6 | O31: 523.3 | P31: 578.1 | Q31: 409.2 | R31: 1144.7 | S31: 352.4 | T31: 227.1 | U31: 198.5 | V31: 206.3 | W31: 236.1 | X31: 329 | Y31: 204 | Z31: 403.7 | AA31: 123.1 | AB31: 195.2 | AC31: 134.2 | AD31: 222.3 | AE31: 171 | AF31: 212.8 | AG31: 88.9 | AH31: 131.4 | AI31: 98.7 | AJ31: 198.7 | AK31: 136.2 | AL31: 130.6 | AM31: 130.5 | AN31: 99.7 | AO31: 134.8 | AP31: 85.1 | AQ31: 77.9 | AR31: 117.5 | AS31: 92.4 | AT31: 88.2 | AU31: 89 | AV31: 88.3 | AW31: 54.4 | AX31: 78.1 | AY31: 70.4 | AZ31: 35.5 | BA31: 64.2 | BB31: 54 | BC31: 69.7 | BD31: 51.7 | BE31: 34.9 | BF31: 45.5 | BG31: 47.6 | BH31: 45.5 | BI31: 18.2 | BJ31: 40.4 | BK31: 62.7 | BL31: 21.5 | BM31: 32.1 | BN31: 14.1 | BO31: 28.1 | BP31: 57.6 | BQ31: 101
A32: 2018-19 | B32: 18286.7 | C32: 1814.5 | D32: 5405.5 | E32: 3794 | F32: 6968.6 | G32: 302.1 | I32: 2 | J32: 3923.7 | K32: 1630.9 | L32: 446.5 | M32: 568.3 | N32: 545.4 | O32: 570 | P32: 526.6 | Q32: 401 | R32: 1565.6 | S32: 400.4 | T32: 234.4 | U32: 219 | V32: 210.5 | W32: 250.5 | X32: 388.4 | Y32: 209.5 | Z32: 368.2 | AA32: 126.7 | AB32: 192.3 | AC32: 189.7 | AD32: 209.5 | AE32: 190.5 | AF32: 273.7 | AG32: 80.7 | AH32: 160.3 | AI32: 106.6 | AJ32: 206.8 | AK32: 116 | AL32: 166.8 | AM32: 193.9 | AN32: 108.3 | AO32: 171.1 | AP32: 94.8 | AQ32: 79.7 | AR32: 114.8 | AS32: 109.7 | AT32: 109.7 | AU32: 68.5 | AV32: 81.1 | AW32: 59.8 | AX32: 93.9 | AY32: 79.2 | AZ32: 37.4 | BA32: 45.6 | BB32: 66.2 | BC32: 65.1 | BD32: 58.6 | BE32: 52.5 | BF32: 59.2 | BG32: 52.8 | BH32: 57.4 | BI32: 22.8 | BJ32: 42.9 | BK32: 62.7 | BL32: 25.3 | BM32: 28.6 | BN32: 14.1 | BO32: 25.8 | BP32: 57.2 | BQ32: 93.1
A33: 2019-20 | B33: 16836.5 | C33: 1873.6 | D33: 5135.3 | E33: 3493.1 | F33: 6049.6 | G33: 284.7 | I33: 0.2 | J33: 3820.7 | K33: 1492.1 | L33: 480 | M33: 571.8 | N33: 569.1 | O33: 527.9 | P33: 481.9 | Q33: 321.6 | R33: 822.9 | S33: 378.8 | T33: 220.6 | U33: 220.3 | V33: 215.5 | W33: 202.6 | X33: 321.4 | Y33: 210.6 | Z33: 293.6 | AA33: 135.6 | AB33: 168.1 | AC33: 175.8 | AD33: 207.5 | AE33: 173.4 | AF33: 233.8 | AG33: 121.1 | AH33: 135.9 | AI33: 101.9 | AJ33: 195.8 | AK33: 151.1 | AL33: 155.4 | AM33: 178.3 | AN33: 105.6 | AO33: 156.5 | AP33: 97 | AQ33: 84 | AR33: 96.4 | AS33: 108.6 | AT33: 101.5 | AU33: 111.7 | AV33: 77.7 | AW33: 60.7 | AX33: 92.2 | AY33: 76.3 | AZ33: 32.1 | BA33: 60.8 | BB33: 47.9 | BC33: 57.3 | BD33: 42.9 | BE33: 59.9 | BF33: 44.4 | BG33: 47.4 | BH33: 54.7 | BI33: 16.3 | BJ33: 40.2 | BK33: 62.9 | BL33: 30.6 | BM33: 33.6 | BN33: 16 | BO33: 25.7 | BP33: 51.6 | BQ33: 314.9
A34: 2020-21 | B34: 15872.5 | C34: 1622.7 | D34: 5635.4 | E34: 3227.2 | F34: 5044.8 | G34: 342.3 | I34: 0 | J34: 4423.8 | K34: 1301 | L34: 452.5 | M34: 417 | N34: 502.8 | O34: 477.1 | P34: 460.9 | Q34: 271.4 | R34: 897.6 | S34: 276.8 | T34: 279.1 | U34: 247.3 | V34: 239.2 | W34: 181.1 | X34: 310.2 | Y34: 227.2 | Z34: 234.9 | AA34: 111.9 | AB34: 156.7 | AC34: 185.5 | AD34: 174 | AE34: 133.8 | AF34: 238.7 | AG34: 141.4 | AH34: 93.9 | AI34: 79.6 | AJ34: 201.5 | AK34: 91.8 | AL34: 79.5 | AM34: 109 | AN34: 88.5 | AO34: 135.8 | AP34: 107 | AQ34: 64.6 | AR34: 102.6 | AS34: 81.9 | AT34: 92.2 | AU34: 95.3 | AV34: 90 | AW34: 81.4 | AX34: 81.6 | AY34: 84 | AZ34: 15 | BA34: 75.7 | BB34: 55.7 | BC34: 52.4 | BD34: 43.2 | BE34: 52.1 | BF34: 20.6 | BG34: 52.9 | BH34: 54.5 | BI34: 13.1 | BJ34: 29.5 | BK34: 45.9 | BL34: 22.6 | BM34: 38.8 | BN34: 17.4 | BO34: 24.9 | BP34: 56.9 | BQ34: 101.9
